Workbook

Sheet Stock
A1: ลำดับ | B1: Ref. | C1: รายการ | D1: ตัวโชว์ | E1: สต็อก | F1: รวม
A2: 1 | B2: =_xlfn.XLOOKUP(C2,Ref!D:D,Ref!A:A,"ไม่พบ") -> 0 | F2: =SUM(D2:E2) -> 0
A3: 2 | B3: =_xlfn.XLOOKUP(C3,Ref!D:D,Ref!A:A,"ไม่พบ") -> 0 | F3: =SUM(D3:E3) -> 0
A4: 3 | B4: =_xlfn.XLOOKUP(C4,Ref!D:D,Ref!A:A,"ไม่พบ") -> 0 | F4: =SUM(D4:E4) -> 0
A5: 4 | B5: =_xlfn.XLOOKUP(C5,Ref!D:D,Ref!A:A,"ไม่พบ") -> 0 | F5: =SUM(D5:E5) -> 0
A6: 5 | B6: =_xlfn.XLOOKUP(C6,Ref!D:D,Ref!A:A,"ไม่พบ") -> 0 | F6: =SUM(D6:E6) -> 0
A7: 6 | B7: =_xlfn.XLOOKUP(C7,Ref!D:D,Ref!A:A,"ไม่พบ") -> 0 | F7: =SUM(D7:E7) -> 0
A8: 7 | B8: =_xlfn.XLOOKUP(C8,Ref!D:D,Ref!A:A,"ไม่พบ") -> 0 | F8: =SUM(D8:E8) -> 0
A9: 8 | B9: =_xlfn.XLOOKUP(C9,Ref!D:D,Ref!A:A,"ไม่พบ") -> 0 | F9: =SUM(D9:E9) -> 0
A10: 9 | B10: =_xlfn.XLOOKUP(C10,Ref!D:D,Ref!A:A,"ไม่พบ") -> 0 | F10: =SUM(D10:E10) -> 0
A11: 10 | B11: =_xlfn.XLOOKUP(C11,Ref!D:D,Ref!A:A,"ไม่พบ") -> 0 | F11: =SUM(D11:E11) -> 0
A12: 11 | B12: =_xlfn.XLOOKUP(C12,Ref!D:D,Ref!A:A,"ไม่พบ") -> 0 | F12: =SUM(D12:E12) -> 0
A13: 12 | B13: =_xlfn.XLOOKUP(C13,Ref!D:D,Ref!A:A,"ไม่พบ") -> 0 | F13: =SUM(D13:E13) -> 0
... A26: 25 | B26: =_xlfn.XLOOKUP(C26,Ref!D:D,Ref!A:A,"ไม่พบ") -> 0 | F26: =SUM(D26:E26) -> 0
C27: รวมทั้งหมด | D27: =SUM(D2:D26) -> 0 | E27: =SUM(E2:E26) -> 0 | F27: =SUM(F2:F26) -> 0
C29: ชื่องาน:
C30: วันที่:
C31: ลงชื่อ: ธนศักดิ์ (จี๊ป)
C32: วันที่แจ้งเรื่อง:

Sheet Event
A1: ลำดับ | B1: Ref. | C1: รายการ | D1: ตัวโชว์ | E1: สต็อก | F1: รวม
A2: 1 | B2: =_xlfn.XLOOKUP(C2,Ref!D:D,Ref!A:A,"ไม่พบ") -> 0 | F2: =SUM(D2:E2) -> 0
A3: 2 | B3: =_xlfn.XLOOKUP(C3,Ref!D:D,Ref!A:A,"ไม่พบ") -> 0 | F3: =SUM(D3:E3) -> 0
A4: 3 | B4: =_xlfn.XLOOKUP(C4,Ref!D:D,Ref!A:A,"ไม่พบ") -> 0 | F4: =SUM(D4:E4) -> 0
A5: 4 | B5: =_xlfn.XLOOKUP(C5,Ref!D:D,Ref!A:A,"ไม่พบ") -> 0 | F5: =SUM(D5:E5) -> 0
A6: 5 | B6: =_xlfn.XLOOKUP(C6,Ref!D:D,Ref!A:A,"ไม่พบ") -> 0 | F6: =SUM(D6:E6) -> 0
A7: 6 | B7: =_xlfn.XLOOKUP(C7,Ref!D:D,Ref!A:A,"ไม่พบ") -> 0 | F7: =SUM(D7:E7) -> 0
A8: 7 | B8: =_xlfn.XLOOKUP(C8,Ref!D:D,Ref!A:A,"ไม่พบ") -> 0 | F8: =SUM(D8:E8) -> 0
A9: 8 | B9: =_xlfn.XLOOKUP(C9,Ref!D:D,Ref!A:A,"ไม่พบ") -> 0 | F9: =SUM(D9:E9) -> 0
A10: 9 | B10: =_xlfn.XLOOKUP(C10,Ref!D:D,Ref!A:A,"ไม่พบ") -> 0 | F10: =SUM(D10:E10) -> 0
A11: 10 | B11: =_xlfn.XLOOKUP(C11,Ref!D:D,Ref!A:A,"ไม่พบ") -> 0 | F11: =SUM(D11:E11) -> 0
A12: 11 | B12: =_xlfn.XLOOKUP(C12,Ref!D:D,Ref!A:A,"ไม่พบ") -> 0 | F12: =SUM(D12:E12) -> 0
A13: 12 | B13: =_xlfn.XLOOKUP(C13,Ref!D:D,Ref!A:A,"ไม่พบ") -> 0 | F13: =SUM(D13:E13) -> 0
... A26: 25 | B26: =_xlfn.XLOOKUP(C26,Ref!D:D,Ref!A:A,"ไม่พบ") -> 0 | F26: =SUM(D26:E26) -> 0
C27: รวมทั้งหมด | D27: =SUM(D2:D26) -> 0 | E27: =SUM(E2:E26) -> 0 | F27: =SUM(F2:F26) -> 0
C29: ชื่องาน:
C30: สถานที่:
C31: ระยะเวลาจัดงาน:
C32: ติดตั้ง:
C33: รื้อถอน:
C34: เบอร์ติดต่อ:
C35: ลงชื่อ: ธนศักดิ์ (จี๊ป)
C36: วันที่แจ้งเรื่อง:

Sheet C.Stock
A1: งาน:
A2: สถานที่จัดงาน:
A3: วันที่แสดงงาน:
A4: ลำดับ | B4: ODOO | C4: รายการสินค้า | D4: สต็อค | E4: xx/xx/xx | G4: xx/xx/xx | I4: xx/xx/xx | K4: xx/xx/xx | M4: xx/xx/xx | O4: xx/xx/xx | Q4: xx/xx/xx | S4: xx/xx/xx | U4: xx/xx/xx | W4: xx/xx/xx | Y4: xx/xx/xx | AA4: xx/xx/xx
E5: เข้า | F5: ออก | G5: เข้า | H5: ออก | I5: เข้า | J5: ออก | K5: เข้า | L5: ออก | M5: เข้า | N5: ออก | O5: เข้า | P5: ออก | Q5: เข้า | R5: ออก | S5: เข้า | T5: ออก | U5: เข้า | V5: ออก | W5: เข้า | X5: ออก | Y5: เข้า | Z5: ออก | AA5: เข้า | AB5: ออก
A6: 1 | B6: =_xlfn.XLOOKUP(A6,Event!A:A,Event!B:B," ") -> 0 | C6: =_xlfn.XLOOKUP(A6,Event!A:A,Event!C:C," ") -> 0 | D6: =_xlfn.XLOOKUP(A6,Event!A:A,Event!E:E," ") -> 0
A7: 2 | B7: =_xlfn.XLOOKUP(A7,Event!A:A,Event!B:B," ") -> 0 | C7: =_xlfn.XLOOKUP(A7,Event!A:A,Event!C:C," ") -> 0 | D7: =_xlfn.XLOOKUP(A7,Event!A:A,Event!E:E," ") -> 0
A8: 3 | B8: =_xlfn.XLOOKUP(A8,Event!A:A,Event!B:B," ") -> 0 | C8: =_xlfn.XLOOKUP(A8,Event!A:A,Event!C:C," ") -> 0 | D8: =_xlfn.XLOOKUP(A8,Event!A:A,Event!E:E," ") -> 0
A9: 4 | B9: =_xlfn.XLOOKUP(A9,Event!A:A,Event!B:B," ") -> 0 | C9: =_xlfn.XLOOKUP(A9,Event!A:A,Event!C:C," ") -> 0 | D9: =_xlfn.XLOOKUP(A9,Event!A:A,Event!E:E," ") -> 0
A10: 5 | B10: =_xlfn.XLOOKUP(A10,Event!A:A,Event!B:B," ") -> 0 | C10: =_xlfn.XLOOKUP(A10,Event!A:A,Event!C:C," ") -> 0 | D10: =_xlfn.XLOOKUP(A10,Event!A:A,Event!E:E," ") -> 0
A11: 6 | B11: =_xlfn.XLOOKUP(A11,Event!A:A,Event!B:B," ") -> 0 | C11: =_xlfn.XLOOKUP(A11,Event!A:A,Event!C:C," ") -> 0 | D11: =_xlfn.XLOOKUP(A11,Event!A:A,Event!E:E," ") -> 0
A12: 7 | B12: =_xlfn.XLOOKUP(A12,Event!A:A,Event!B:B," ") -> 0 | C12: =_xlfn.XLOOKUP(A12,Event!A:A,Event!C:C," ") -> 0 | D12: =_xlfn.XLOOKUP(A12,Event!A:A,Event!E:E," ") -> 0
A13: 8 | B13: =_xlfn.XLOOKUP(A13,Event!A:A,Event!B:B," ") -> 0 | C13: =_xlfn.XLOOKUP(A13,Event!A:A,Event!C:C," ") -> 0 | D13: =_xlfn.XLOOKUP(A13,Event!A:A,Event!E:E," ") -> 0
A14: 9 | B14: =_xlfn.XLOOKUP(A14,Event!A:A,Event!B:B," ") -> 0 | C14: =_xlfn.XLOOKUP(A14,Event!A:A,Event!C:C," ") -> 0 | D14: =_xlfn.XLOOKUP(A14,Event!A:A,Event!E:E," ") -> 0
A15: 10 | B15: =_xlfn.XLOOKUP(A15,Event!A:A,Event!B:B," ") -> 0 | C15: =_xlfn.XLOOKUP(A15,Event!A:A,Event!C:C," ") -> 0 | D15: =_xlfn.XLOOKUP(A15,Event!A:A,Event!E:E," ") -> 0
A16: 11 | B16: =_xlfn.XLOOKUP(A16,Event!A:A,Event!B:B," ") -> 0 | C16: =_xlfn.XLOOKUP(A16,Event!A:A,Event!C:C," ") -> 0 | D16: =_xlfn.XLOOKUP(A16,Event!A:A,Event!E:E," ") -> 0
A17: 12 | B17: =_xlfn.XLOOKUP(A17,Event!A:A,Event!B:B," ") -> 0 | C17: =_xlfn.XLOOKUP(A17,Event!A:A,Event!C:C," ") -> 0 | D17: =_xlfn.XLOOKUP(A17,Event!A:A,Event!E:E," ") -> 0
... A30: 25 | B30: =_xlfn.XLOOKUP(A30,Event!A:A,Event!B:B," ") -> 0 | C30: =_xlfn.XLOOKUP(A30,Event!A:A,Event!C:C," ") -> 0 | D30: =_xlfn.XLOOKUP(A30,Event!A:A,Event!E:E," ") -> 0
E34: ผู้ตรวจ | G34: ผู้ตรวจ | I34: ผู้ตรวจ | K34: ผู้ตรวจ | M34: ผู้ตรวจ | O34: ผู้ตรวจ | Q34: ผู้ตรวจ | S34: ผู้ตรวจ | U34: ผู้ตรวจ | W34: ผู้ตรวจ | Y34: ผู้ตรวจ | AA34: ผู้ตรวจ
E39: ผู้ส่ง | G39: ผู้ส่ง | I39: ผู้ส่ง | K39: ผู้ส่ง | M39: ผู้ส่ง | O39: ผู้ส่ง | Q39: ผู้ส่ง | S39: ผู้ส่ง | U39: ผู้ส่ง | W39: ผู้ส่ง | Y39: ผู้ส่ง | AA39: ผู้ส่ง

Sheet C.Demo
A1: งาน:
A2: สถานที่จัดงาน:
A3: วันที่แสดงงาน:
A4: ลำดับ | B4: ODOO | C4: รายการสินค้า | D4: ตัวโชว์ | E4: xx/xx/xx | G4: xx/xx/xx | I4: xx/xx/xx | K4: xx/xx/xx | M4: xx/xx/xx | O4: xx/xx/xx | Q4: xx/xx/xx | S4: xx/xx/xx | U4: xx/xx/xx | W4: xx/xx/xx | Y4: xx/xx/xx | AA4: xx/xx/xx
E5: เข้า | F5: ออก | G5: เข้า | H5: ออก | I5: เข้า | J5: ออก | K5: เข้า | L5: ออก | M5: เข้า | N5: ออก | O5: เข้า | P5: ออก | Q5: เข้า | R5: ออก | S5: เข้า | T5: ออก | U5: เข้า | V5: ออก | W5: เข้า | X5: ออก | Y5: เข้า | Z5: ออก | AA5: เข้า | AB5: ออก
A6: 1 | B6: =_xlfn.XLOOKUP(A6,Event!A:A,Event!B:B," ") -> 0 | C6: =_xlfn.XLOOKUP(A6,Event!A:A,Event!C:C," ") -> 0 | D6: =_xlfn.XLOOKUP(A6,Event!A:A,Event!D:D," ") -> 0
A7: 2 | B7: =_xlfn.XLOOKUP(A7,Event!A:A,Event!B:B," ") -> 0 | C7: =_xlfn.XLOOKUP(A7,Event!A:A,Event!C:C," ") -> 0 | D7: =_xlfn.XLOOKUP(A7,Event!A:A,Event!D:D," ") -> 0
A8: 3 | B8: =_xlfn.XLOOKUP(A8,Event!A:A,Event!B:B," ") -> 0 | C8: =_xlfn.XLOOKUP(A8,Event!A:A,Event!C:C," ") -> 0 | D8: =_xlfn.XLOOKUP(A8,Event!A:A,Event!D:D," ") -> 0
A9: 4 | B9: =_xlfn.XLOOKUP(A9,Event!A:A,Event!B:B," ") -> 0 | C9: =_xlfn.XLOOKUP(A9,Event!A:A,Event!C:C," ") -> 0 | D9: =_xlfn.XLOOKUP(A9,Event!A:A,Event!D:D," ") -> 0
A10: 5 | B10: =_xlfn.XLOOKUP(A10,Event!A:A,Event!B:B," ") -> 0 | C10: =_xlfn.XLOOKUP(A10,Event!A:A,Event!C:C," ") -> 0 | D10: =_xlfn.XLOOKUP(A10,Event!A:A,Event!D:D," ") -> 0
A11: 6 | B11: =_xlfn.XLOOKUP(A11,Event!A:A,Event!B:B," ") -> 0 | C11: =_xlfn.XLOOKUP(A11,Event!A:A,Event!C:C," ") -> 0 | D11: =_xlfn.XLOOKUP(A11,Event!A:A,Event!D:D," ") -> 0
A12: 7 | B12: =_xlfn.XLOOKUP(A12,Event!A:A,Event!B:B," ") -> 0 | C12: =_xlfn.XLOOKUP(A12,Event!A:A,Event!C:C," ") -> 0 | D12: =_xlfn.XLOOKUP(A12,Event!A:A,Event!D:D," ") -> 0
A13: 8 | B13: =_xlfn.XLOOKUP(A13,Event!A:A,Event!B:B," ") -> 0 | C13: =_xlfn.XLOOKUP(A13,Event!A:A,Event!C:C," ") -> 0 | D13: =_xlfn.XLOOKUP(A13,Event!A:A,Event!D:D," ") -> 0
A14: 9 | B14: =_xlfn.XLOOKUP(A14,Event!A:A,Event!B:B," ") -> 0 | C14: =_xlfn.XLOOKUP(A14,Event!A:A,Event!C:C," ") -> 0 | D14: =_xlfn.XLOOKUP(A14,Event!A:A,Event!D:D," ") -> 0
A15: 10 | B15: =_xlfn.XLOOKUP(A15,Event!A:A,Event!B:B," ") -> 0 | C15: =_xlfn.XLOOKUP(A15,Event!A:A,Event!C:C," ") -> 0 | D15: =_xlfn.XLOOKUP(A15,Event!A:A,Event!D:D," ") -> 0
A16: 11 | B16: =_xlfn.XLOOKUP(A16,Event!A:A,Event!B:B," ") -> 0 | C16: =_xlfn.XLOOKUP(A16,Event!A:A,Event!C:C," ") -> 0 | D16: =_xlfn.XLOOKUP(A16,Event!A:A,Event!D:D," ") -> 0
A17: 12 | B17: =_xlfn.XLOOKUP(A17,Event!A:A,Event!B:B," ") -> 0 | C17: =_xlfn.XLOOKUP(A17,Event!A:A,Event!C:C," ") -> 0 | D17: =_xlfn.XLOOKUP(A17,Event!A:A,Event!D:D," ") -> 0
... A30: 25 | B30: =_xlfn.XLOOKUP(A30,Event!A:A,Event!B:B," ") -> 0 | C30: =_xlfn.XLOOKUP(A30,Event!A:A,Event!C:C," ") -> 0 | D30: =_xlfn.XLOOKUP(A30,Event!A:A,Event!D:D," ") -> 0
E34: ผู้ตรวจ | G34: ผู้ตรวจ | I34: ผู้ตรวจ | K34: ผู้ตรวจ | M34: ผู้ตรวจ | O34: ผู้ตรวจ | Q34: ผู้ตรวจ | S34: ผู้ตรวจ | U34: ผู้ตรวจ | W34: ผู้ตรวจ | Y34: ผู้ตรวจ | AA34: ผู้ตรวจ
E39: ผู้ส่ง | G39: ผู้ส่ง | I39: ผู้ส่ง | K39: ผู้ส่ง | M39: ผู้ส่ง | O39: ผู้ส่ง | Q39: ผู้ส่ง | S39: ผู้ส่ง | U39: ผู้ส่ง | W39: ผู้ส่ง | Y39: ผู้ส่ง | AA39: ผู้ส่ง

Sheet Ref
A1: Odoo | B1: Barcode | C1: Product Name | D1: Arrange Name | E1: Black Price | F1: Red Price
A2: A10018 | B2: 8859845000186 | C2: ERGO MOUSE 01 | D2: ERGO MOUSE 01 | E2: 1590 | F2: 999
A3: A10072 | B3: 8859845000414 | C3: RGB DESK MAT (KEYBOARD PAD) | D3: RGB DESK MAT (KEYBOARD PAD) | E3: 1190 | F3: 690
A4: A10073 | B4: 8859845000421 | C4: RGB MOUSE PAD | D4: RGB MOUSE PAD | E4: 790 | F4: 490
A5: A10074 | B5: 8859845000438 | C5: YALE KEYBOARD WRIST PAD | D5: YALE KEYBOARD WRIST PAD | E5: 690 | F5: 390
A6: A10075 | B6: 8859845000445 | C6: YALE MOUSE PAD | D6: YALE MOUSE PAD | E6: 790 | F6: 490
A7: A10023 | B7: 8859845000230 | C7: Aluminum Laptop Riser 01 | D7: ALUMINUM LAPTOP RISER 01 | E7: 1590 | F7: 999
A8: A10067 | B8: 8859845000360 | C8: PORTO PHONE & TABLET STAND | D8: PORTO PHONE & TABLET STAND | E8: 1399 | F8: 999
A9: A10188 | B9: 8859845000575 | C9: LIMA Mobile Phone Holder | D9: LIMA MOBILE PHONE HOLDER | E9: 790 | F9: 599
A10: A10189 | B10: 8859845000582 | C10: SKI Laptop Riser | D10: SKI LAPTOP RISER | E10: 690 | F10: 499
A11: A10190 | B11: 8859845000599 | C11: HAVANA Laptop Riser | D11: HAVANA LAPTOP RISER | E11: 2590 | F11: 1990
A12: A10180 | B12: 8859845000506 | C12: ลูกบอลบริหารมือ EGG GRIP BALL | D12: EGG GRIP BALL | E12: 190 | F12: 149
A13: A10183 | B13: 8859845000537 | C13: SPIDER Finger Stretcher ยางยืดบริหารนิ้วมือ | D13: SPIDER FINGER STRETCHER | E13: 190 | F13: 149
... A36: A10041 | B36: 8859845000896 | C36: Mesh Cable Tray | D36: MESH CABLE TRAY | E36: 1090 | F36: 790
A37: A10042 | C37: Cable Tube white for Sit2Stand | D37: CABLE TUBE WHITE FOR SIT2STAND | E37: 1590 | F37: 990
A38: A10043 | C38: Cable Tube black for Sit2Stand | D38: CABLE TUBE BLACK FOR SIT2STAND | E38: 1590 | F38: 990
A39: A10044 | C39: Cable Snake white for Sit2Stand | D39: CABLE SNAKE WHITE FOR SIT2STAND | E39: 1290 | F39: 790
A40: A10045 | C40: Cable Snake black for Sit2Stand | D40: CABLE SNAKE BLACK FOR SIT2STAND | E40: 1290 | F40: 790
A41: A10046 | C41: Cable Cover white for Sit2Stand | D41: CABLE COVER WHITE FOR SIT2STAND | E41: 1290 | F41: 790
A42: A10047 | C42: Cable Cover black for Sit2Stand | D42: CABLE COVER BLACK FOR SIT2STAND | E42: 1290 | F42: 790
A43: A10227 | B43: 8859845002975 | C43: LAPTOP PRO Laptop Table on Chair (Black) | D43: LAPTOP PRO LAPTOP TABLE ON CHAIR (BLACK) | E43: 3390 | F43: 1990
A44: A10228 | B44: 8859845002982 | C44: LAPTOP PRO Laptop Table on Chair (Grey) | D44: LAPTOP PRO LAPTOP TABLE ON CHAIR (GREY) | E44: 3390 | F44: 1990
A45: A10010 | B45: 8859845000148 | C45: POWER STRIP HOLDER (MH01-2) | D45: POWER STRIP HOLDER (MH01-2) | E45: 590 | F45: 490
A46: A10013 | B46: 8859845000162 | C46: Smart Keyboard Tray -Black | D46: SMART KEYBOARD TRAY -BLACK | E46: 7100 | F46: 4990
A47: A10028 | B47: 8859845000285 | C47: COMBI CHAIR | D47: Combi Chair | E47: 2590 | F47: 1690
A48: A10216 | B48: 8859845001619 | C48: COMBI CHAIR JUMBO GRAY | D48: Combi Chair Jumbo Gray | E48: 2760 | F48: 1790
A49: A10076 | B49: 8859845000452 | C49: BRIX ARMREST CUSHION | D49: Brix Armrest Cushion | E49: 690 | F49: 490
A50: A10148 | B50: 8859845000469 | C50: PHYSIO ERGO CUSHION FOR HIGH BACK (Middle Back) | D50: Physio Ergo Cushion For Middle Back | E50: 2490 | F50: 1290
A51: A10149 | B51: 8859845000476 | C51: PHYSIO ERGO CUSHION FOR LOWER BACK | D51: Physio Ergo Cushion For Lower Back | E51: 2490 | F51: 1290
A52: A10150 | B52: 8859845000483 | C52: PHYSIO ERGO SEAT CUSHION | D52: Physio Ergo Seat Cushion | E52: 1390 | F52: 990
A53: A10207 | B53: 8859845000605 | C53: LIMO Car Seat Back Cushion | D53: Limo Car Seat Back Cushion | E53: 990 | F53: 599
A54: A10208 | B54: 8859845000612 | C54: MOBIL Car Seat Neck Cushion | D54: Mobil Car Seat Neck Cushion | E54: 590 | F54: 399
... A62: A10030 | B62: 8859845001589 | C62: MIYO-HIP UP CUSHION-MEMORY FOAM | D62: Miyo Hip Up Cushion | E62: 1550 | F62: 990
A63: C10038 | C63: เก้าอี้ รุ่น ANOMOUS | D63: เก้าอี้เพื่อสุขภาพ รุ่น Anomous | E63: 8400 | F63: 4990
A64: C10071 | C64: เก้าอี้ รุ่น KONOMOUS | D64: เก้าอี้เพื่อสุขภาพ รุ่น Konomous | E64: 8400 | F64: 4990
A65: C10039 | C65: เก้าอี้ รุ่น Bergen-All Black | D65: เก้าอี้เพื่อสุขภาพ รุ่น Bergen All Black | E65: 34900 | F65: 19990
A66: C10040 | B66: 8859845001367 | C66: เก้าอี้ รุ่น Bergen | D66: เก้าอี้เพื่อสุขภาพ รุ่น Bergen | E66: 34900 | F66: 19990
A67: C10041 | B67: 8859845001992 | C67: เก้าอี้รุ่น Beyond-Gray | D67: เก้าอี้เพื่อสุขภาพ รุ่น Beyond-Gray | E67: 34500 | F67: 22900
A68: C10043 | C68: เก้าอี้เพื่อสุขภาพ รุ่น Butterfly01BMM | D68: เก้าอี้เพื่อสุขภาพ รุ่น Butterfly01Bmm | E68: 34500 | F68: 22900
A69: C10044 | B69: 8859845002746 | C69: เก้าอี้สำนักงานเพื่อสุขภาพ รุ่น Butterfly01GMM | D69: เก้าอี้เพื่อสุขภาพ รุ่น Butterfly01Gmm | E69: 34500 | F69: 22900
...
